Workbook

Sheet README
A1: Edge Spectrum V9 - Standardized Model Package
A3: This workbook converts your uploaded V9 dataset into a standardized DU/CED model. Edit DU/day and CED% on the Standardized_Model sheet to test new assumptions.
A5: Sheet | B5: Purpose
A6: README | B6: How the model works and how to use the workbook
A7: Original_V9 | B7: Clean import of all 180 rows from edge_analysis9.md
A8: Standardized_Model | B8: Editable model with DU/day + CED% + standardized horizon returns
A9: Category_Summary | B9: Category-level rollups based on the standardized model
A10: Dashboard | B10: Simple visuals for average 1Y / 10Y standardized return and DU/day
A12: Source | B12: /mnt/data/edge_analysis9.md
A14: Standardization formulas
A15: Field | B15: Formula / meaning
A16: DU | B16: Decision Units. One discrete capital-at-risk decision.
A17: CED | B17: Capital Exposure per Decision. Entered as % of bankroll/exposure per decision.
A18: Linear rows | B18: Return = DU × CED × Edge
A19: Compound rows | B19: Return = (1 + Edge × CED)^Years - 1
A20: 1 Decision (compound) | B20: Years per decision = 1 / (DU/day × 365)
A21: Important | B21: These are editable scenario assumptions, not claims about guaranteed real-world results.
A23: Suggested defaults are intentionally editable. Casino, poker, and trading rows can swing dramatically based on actual volume and unit size, so use this workbook as a scenario model.

Sheet Original_V9
A1: ItemNo | B1: Category | C1: OriginalCategoryType | D1: Subsection | E1: ModelBasis | F1: Layer | G1: Name | H1: OriginalEdgePct_Input | I1: 1 Trade | J1: 1 Bet | K1: 1 Day | L1: 1 Week | M1: 1 Month | N1: 1 Year | O1: 5 Years | P1: 10 Years
A2: 1 | B2: Stock Market | C2: Compound | E2: Compound | F2: raw | G2: NASDAQ 100 (QQQ) | H2: 12.5 | I2: 0.05 | K2: 0.05 | L2: 0.23 | M2: 0.99 | N2: 12.5 | O2: 80.2 | P2: 224.73
A3: 2 | B3: Stock Market | C3: Compound | E3: Compound | F3: raw | G3: S&P 500 Growth (IVW) | H3: 12 | I3: 0.04 | K3: 0.04 | L3: 0.22 | M3: 0.95 | N3: 12 | O3: 76.23 | P3: 210.58
A4: 3 | B4: Stock Market | C4: Compound | E4: Compound | F4: raw | G4: Small-Cap Value (VBR) | H4: 11.5 | I4: 0.04 | K4: 0.04 | L4: 0.21 | M4: 0.91 | N4: 11.5 | O4: 72.34 | P4: 196.99
A5: 4 | B5: Stock Market | C5: Compound | E5: Compound | F5: raw | G5: S&P MidCap 400 (MDY) | H5: 11 | I5: 0.04 | K5: 0.04 | L5: 0.2 | M5: 0.87 | N5: 11 | O5: 68.51 | P5: 183.94
A6: 5 | B6: Stock Market | C6: Compound | E6: Compound | F6: raw | G6: Dividend Aristocrats (NOBL) | H6: 10.5 | I6: 0.04 | K6: 0.04 | L6: 0.19 | M6: 0.84 | N6: 10.5 | O6: 64.74 | P6: 171.41
A7: 6 | B7: Stock Market | C7: Compound | E7: Compound | F7: raw | G7: Total US Stock Market (VTI) | H7: 10.2 | I7: 0.04 | K7: 0.04 | L7: 0.19 | M7: 0.81 | N7: 10.2 | O7: 62.52 | P7: 164.13
A8: 7 | B8: Stock Market | C8: Compound | E8: Compound | F8: raw | G8: S&P 500 Index (SPY/VOO) | H8: 10 | I8: 0.04 | K8: 0.04 | L8: 0.18 | M8: 0.8 | N8: 10 | O8: 61.05 | P8: 159.37
A9: 8 | B9: Stock Market | C9: Compound | E9: Compound | F9: raw | G9: S&P 500 Equal Weight (RSP) | H9: 10 | I9: 0.04 | K9: 0.04 | L9: 0.18 | M9: 0.8 | N9: 10 | O9: 61.05 | P9: 159.37
A10: 9 | B10: Stock Market | C10: Compound | E10: Compound | F10: raw | G10: Dow Jones Industrial (DIA) | H10: 9.5 | I10: 0.04 | K10: 0.04 | L10: 0.17 | M10: 0.76 | N10: 9.5 | O10: 57.42 | P10: 147.82
A11: 10 | B11: Stock Market | C11: Compound | E11: Compound | F11: raw | G11: S&P 500 Value (IVE) | H11: 9.5 | I11: 0.04 | K11: 0.04 | L11: 0.17 | M11: 0.76 | N11: 9.5 | O11: 57.42 | P11: 147.82
A12: 11 | B12: Stock Market | C12: Compound | E12: Compound | F12: raw | G12: Russell 2000 Small Cap (IWM) | H12: 8.5 | I12: 0.03 | K12: 0.03 | L12: 0.16 | M12: 0.68 | N12: 8.5 | O12: 50.37 | P12: 126.1
A13: 12 | B13: Stock Market | C13: Compound | E13: Compound | F13: raw | G13: REIT Index ETF (VNQ) | H13: 8 | I13: 0.03 | K13: 0.03 | L13: 0.15 | M13: 0.64 | N13: 8 | O13: 46.93 | P13: 115.89
... A72: 10 | B72: Cryptocurrency | C72: Compound | E72: Compound | F72: tax | G72: Ethereum After LTCG Tax (20%) | H72: 8 | I72: 0.03 | K72: 0.03 | L72: 0.15 | M72: 0.64 | N72: 8 | O72: 46.93 | P72: 115.89
A73: 1 | B73: Options & Derivatives | C73: Mixed | D73: Compound Entries | E73: Compound | F73: raw | G73: Iron Condor Selling | H73: 10 | I73: 0.04 | K73: 0.04 | L73: 0.18 | M73: 0.8 | N73: 10 | O73: 61.05 | P73: 159.37
A74: 2 | B74: Options & Derivatives | C74: Mixed | D74: Compound Entries | E74: Compound | F74: raw | G74: Cash-Secured Put Selling | H74: 8 | I74: 0.03 | K74: 0.03 | L74: 0.15 | M74: 0.64 | N74: 8 | O74: 46.93 | P74: 115.89
A75: 3 | B75: Options & Derivatives | C75: Mixed | D75: Compound Entries | E75: Compound | F75: raw | G75: Covered Call Writing | H75: 7 | I75: 0.03 | K75: 0.03 | L75: 0.13 | M75: 0.57 | N75: 7 | O75: 40.26 | P75: 96.72
A76: 4 | B76: Options & Derivatives | C76: Mixed | D76: Compound Entries | E76: Compound | F76: raw | G76: Managed Futures / CTA | H76: 3 | I76: 0.01 | K76: 0.01 | L76: 0.06 | M76: 0.25 | N76: 3 | O76: 15.93 | P76: 34.39
A77: 11 | B77: Options & Derivatives | C77: Mixed | D77: Compound Entries | E77: Compound | F77: tax | G77: Iron Condor After STCG Tax (37%) | H77: 6.3 | I77: 0.02 | K77: 0.02 | L77: 0.12 | M77: 0.51 | N77: 6.3 | O77: 35.73 | P77: 84.22
A78: 12 | B78: Options & Derivatives | C78: Mixed | D78: Compound Entries | E78: Compound | F78: tax | G78: Cash-Secured Put After STCG Tax (37%) | H78: 5.04 | I78: 0.02 | K78: 0.02 | L78: 0.09 | M78: 0.41 | N78: 5.04 | O78: 27.87 | P78: 63.51
A79: 13 | B79: Options & Derivatives | C79: Mixed | D79: Compound Entries | E79: Compound | F79: tax | G79: Covered Call After STCG Tax (37%) | H79: 4.41 | I79: 0.02 | K79: 0.02 | L79: 0.08 | M79: 0.36 | N79: 4.41 | O79: 24.08 | P79: 53.96
A80: 14 | B80: Options & Derivatives | C80: Mixed | D80: Compound Entries | E80: Compound | F80: tax | G80: Managed Futures After 60/40 Tax (26.8%) | H80: 2.2 | I80: 0.01 | K80: 0.01 | L80: 0.04 | M80: 0.18 | N80: 2.2 | O80: 11.49 | P80: 24.31
A81: 5 | B81: Options & Derivatives | C81: Mixed | D81: Linear Entries | E81: Linear | F81: raw | G81: Commodity Futures (Retail) | H81: -8 | J81: -0.8 | K81: -1.6 | L81: -9.6 | M81: -41.6 | N81: -500 | O81: -2500 | P81: -5000
A82: 6 | B82: Options & Derivatives | C82: Mixed | D82: Linear Entries | E82: Linear | F82: raw | G82: ATM Options Buying (30-Day) | H82: -15 | J82: -1.5 | K82: -3 | L82: -18 | M82: -78 | N82: -937.5 | O82: -4687.5 | P82: -9375
A83: 7 | B83: Options & Derivatives | C83: Mixed | D83: Linear Entries | E83: Linear | F83: raw | G83: Leveraged Futures Day Trading | H83: -25 | J83: -2.5 | K83: -5 | L83: -30 | M83: -130 | N83: -1562.5 | O83: -7812.5 | P83: -15625
A84: 8 | B84: Options & Derivatives | C84: Mixed | D84: Linear Entries | E84: Linear | F84: raw | G84: OTM Options Buying (30-Day) | H84: -35 | J84: -3.5 | K84: -7 | L84: -42 | M84: -182 | N84: -2187.5 | O84: -10937.5 | P84: -21875
A85: 9 | B85: Options & Derivatives | C85: Mixed | D85: Linear Entries | E85: Linear | F85: raw | G85: 0DTE Options (Retail Avg) | H85: -50 | J85: -5 | K85: -10 | L85: -60 | M85: -260 | N85: -3125 | O85: -15625 | P85: -31250
A86: 10 | B86: Options & Derivatives | C86: Mixed | D86: Linear Entries | E86: Linear | F86: raw | G86: Deep OTM Weekly Options | H86: -60 | J86: -6 | K86: -12 | L86: -72 | M86: -312 | N86: -3750 | O86: -18750 | P86: -37500
A87: 1 | B87: Active Trading | C87: Compound | E87: Compound | F87: raw | G87: Systematic Trend Following | H87: 5 | I87: 0.02 | K87: 0.02 | L87: 0.09 | M87: 0.41 | N87: 5 | O87: 27.63 | P87: 62.89
A88: 2 | B88: Active Trading | C88: Compound | E88: Compound | F88: raw | G88: Social/Copy Trading (Retail) | H88: -12 | I88: -0.05 | K88: -0.05 | L88: -0.25 | M88: -1.06 | N88: -12 | O88: -47.23 | P88: -72.15
A89: 3 | B89: Active Trading | C89: Compound | E89: Compound | F89: raw | G89: Momentum Trading (Retail) | H89: -18 | I89: -0.08 | K89: -0.08 | L89: -0.38 | M89: -1.64 | N89: -18 | O89: -62.93 | P89: -86.26
A90: 4 | B90: Active Trading | C90: Compound | E90: Compound | F90: raw | G90: Retail Forex Trading | H90: -25 | I90: -0.11 | K90: -0.11 | L90: -0.55 | M90: -2.37 | N90: -25 | O90: -76.27 | P90: -94.37
A91: 5 | B91: Active Trading | C91: Compound | E91: Compound | F91: raw | G91: CFD Trading (Retail, Leveraged) | H91: -28 | I91: -0.13 | K91: -0.13 | L91: -0.63 | M91: -2.7 | N91: -28 | O91: -80.65 | P91: -96.26
A92: 6 | B92: Active Trading | C92: Compound | E92: Compound | F92: raw | G92: Retail Day Trading | H92: -30 | I92: -0.14 | K92: -0.14 | L92: -0.68 | M92: -2.93 | N92: -30 | O92: -83.19 | P92: -97.18
A93: 7 | B93: Active Trading | C93: Compound | E93: Compound | F93: raw | G93: Crypto Day Trading (Retail) | H93: -35 | I93: -0.17 | K93: -0.17 | L93: -0.83 | M93: -3.53 | N93: -35 | O93: -88.4 | P93: -98.65
A94: 8 | B94: Active Trading | C94: Compound | E94: Compound | F94: raw | G94: Binary Options (Retail) | H94: -40 | I94: -0.2 | K94: -0.2 | L94: -0.98 | M94: -4.17 | N94: -40 | O94: -92.22 | P94: -99.4
A95: 9 | B95: Active Trading | C95: Compound | E95: Compound | F95: tax | G95: Trend Following After STCG Tax (37%) | H95: 3.15 | I95: 0.01 | K95: 0.01 | L95: 0.06 | M95: 0.26 | N95: 3.15 | O95: 16.77 | P95: 36.36
A96: 10 | B96: Active Trading | C96: Compound | E96: Compound | F96: tax | G96: Day Trading After Income Tax (37%) | H96: -30 | I96: -0.14 | K96: -0.14 | L96: -0.68 | M96: -2.93 | N96: -30 | O96: -83.19 | P96: -97.18
A97: 1 | B97: Collectibles | C97: Compound | E97: Compound | F97: raw | G97: Vintage Sports Cards (PSA 10) | H97: 6 | I97: 0.02 | K97: 0.02 | L97: 0.11 | M97: 0.49 | N97: 6 | O97: 33.82 | P97: 79.08
A98: 2 | B98: Collectibles | C98: Compound | E98: Compound | F98: raw | G98: Fine Art (Blue Chip / Old Masters) | H98: 5 | I98: 0.02 | K98: 0.02 | L98: 0.09 | M98: 0.41 | N98: 5 | O98: 27.63 | P98: 62.89
...

Sheet Standardized_Model
A1: ItemNo | B1: Category | C1: Subsection | D1: ModelBasis | E1: Layer | F1: Name | G1: OriginalEdgePct | H1: EdgeInputBasis | I1: DU_per_Day | J1: CED | K1: DU_1_Decision | L1: DU_1_Day | M1: DU_1_Week | N1: DU_1_Month | O1: DU_1_Year | P1: DU_5_Years | Q1: DU_10_Years | R1: Std_1_Decision | S1: Std_1_Day | T1: Std_1_Week | U1: Std_1_Month | V1: Std_1_Year | W1: Std_5_Years | X1: Std_10_Years | Y1: Assumption_Note | Z1: Source
A2: 1 | B2: Stock Market | D2: Compound | E2: raw | F2: NASDAQ 100 (QQQ) | G2: 12.5 | H2: Annualized | I2: 0.02 | J2: 1 | K2: =1 -> 1 | L2: =I2 -> 0.02 | M2: =I2*7 -> 0.14 | N2: =I2*30 -> 0.6 | O2: =I2*365 -> 7.3 | P2: =I2*1825 -> 36.5 | Q2: =I2*3650 -> 73 | R2: =IF(D2="Linear",K2*J2*(G2/100),IF(I2>0,(1+((G2/100)*J2))^(1/(I2*365))-1,0)) -> 0.016265529 | S2: =IF(D2="Linear",L2*J2*(G2/100),(1+((G2/100)*J2))^(1/365)-1) -> 0.00032274532 | T2: =IF(D2="Linear",M2*J2*(G2/100),(1+((G2/100)*J2))^(7/365)-1) -> 0.0022614059 | U2: =IF(D2="Linear",N2*J2*(G2/100),(1+((G2/100)*J2))^(30/365)-1) -> 0.0097278079 | V2: =IF(D2="Linear",O2*J2*(G2/100),(1+((G2/100)*J2))-1) -> 0.125 | W2: =IF(D2="Linear",P2*J2*(G2/100),(1+((G2/100)*J2))^5-1) -> 0.80203247 | X2: =IF(D2="Linear",Q2*J2*(G2/100),(1+((G2/100)*J2))^10-1) -> 2.247321 | Y2: Long-term allocation; roughly 5 portfolio decisions per year | Z2: /mnt/data/edge_analysis9.md
A3: 2 | B3: Stock Market | D3: Compound | E3: raw | F3: S&P 500 Growth (IVW) | G3: 12 | H3: Annualized | I3: 0.02 | J3: 1 | K3: =1 -> 1 | L3: =I3 -> 0.02 | M3: =I3*7 -> 0.14 | N3: =I3*30 -> 0.6 | O3: =I3*365 -> 7.3 | P3: =I3*1825 -> 36.5 | Q3: =I3*3650 -> 73 | R3: =IF(D3="Linear",K3*J3*(G3/100),IF(I3>0,(1+((G3/100)*J3))^(1/(I3*365))-1,0)) -> 0.015645608 | S3: =IF(D3="Linear",L3*J3*(G3/100),(1+((G3/100)*J3))^(1/365)-1) -> 0.00031053776 | T3: =IF(D3="Linear",M3*J3*(G3/100),(1+((G3/100)*J3))^(7/365)-1) -> 0.0021757904 | U3: =IF(D3="Linear",N3*J3*(G3/100),(1+((G3/100)*J3))^(30/365)-1) -> 0.0093582032 | V3: =IF(D3="Linear",O3*J3*(G3/100),(1+((G3/100)*J3))-1) -> 0.12 | W3: =IF(D3="Linear",P3*J3*(G3/100),(1+((G3/100)*J3))^5-1) -> 0.76234168 | X3: =IF(D3="Linear",Q3*J3*(G3/100),(1+((G3/100)*J3))^10-1) -> 2.1058482 | Y3: Long-term allocation; roughly 5 portfolio decisions per year | Z3: /mnt/data/edge_analysis9.md
A4: 3 | B4: Stock Market | D4: Compound | E4: raw | F4: Small-Cap Value (VBR) | G4: 11.5 | H4: Annualized | I4: 0.02 | J4: 1 | K4: =1 -> 1 | L4: =I4 -> 0.02 | M4: =I4*7 -> 0.14 | N4: =I4*30 -> 0.6 | O4: =I4*365 -> 7.3 | P4: =I4*1825 -> 36.5 | Q4: =I4*3650 -> 73 | R4: =IF(D4="Linear",K4*J4*(G4/100),IF(I4>0,(1+((G4/100)*J4))^(1/(I4*365))-1,0)) -> 0.015023294 | S4: =IF(D4="Linear",L4*J4*(G4/100),(1+((G4/100)*J4))^(1/365)-1) -> 0.00029827572 | T4: =IF(D4="Linear",M4*J4*(G4/100),(1+((G4/100)*J4))^(7/365)-1) -> 0.0020897993 | U4: =IF(D4="Linear",N4*J4*(G4/100),(1+((G4/100)*J4))^(30/365)-1) -> 0.0089870809 | V4: =IF(D4="Linear",O4*J4*(G4/100),(1+((G4/100)*J4))-1) -> 0.115 | W4: =IF(D4="Linear",P4*J4*(G4/100),(1+((G4/100)*J4))^5-1) -> 0.72335337 | X4: =IF(D4="Linear",Q4*J4*(G4/100),(1+((G4/100)*J4))^10-1) -> 1.9699468 | Y4: Long-term allocation; roughly 5 portfolio decisions per year | Z4: /mnt/data/edge_analysis9.md
A5: 4 | B5: Stock Market | D5: Compound | E5: raw | F5: S&P MidCap 400 (MDY) | G5: 11 | H5: Annualized | I5: 0.02 | J5: 1 | K5: =1 -> 1 | L5: =I5 -> 0.02 | M5: =I5*7 -> 0.14 | N5: =I5*30 -> 0.6 | O5: =I5*365 -> 7.3 | P5: =I5*1825 -> 36.5 | Q5: =I5*3650 -> 73 | R5: =IF(D5="Linear",K5*J5*(G5/100),IF(I5>0,(1+((G5/100)*J5))^(1/(I5*365))-1,0)) -> 0.014398567 | S5: =IF(D5="Linear",L5*J5*(G5/100),(1+((G5/100)*J5))^(1/365)-1) -> 0.00028595873 | T5: =IF(D5="Linear",M5*J5*(G5/100),(1+((G5/100)*J5))^(7/365)-1) -> 0.0020034291 | U5: =IF(D5="Linear",N5*J5*(G5/100),(1+((G5/100)*J5))^(30/365)-1) -> 0.008614428 | V5: =IF(D5="Linear",O5*J5*(G5/100),(1+((G5/100)*J5))-1) -> 0.11 | W5: =IF(D5="Linear",P5*J5*(G5/100),(1+((G5/100)*J5))^5-1) -> 0.68505816 | X5: =IF(D5="Linear",Q5*J5*(G5/100),(1+((G5/100)*J5))^10-1) -> 1.839421 | Y5: Long-term allocation; roughly 5 portfolio decisions per year | Z5: /mnt/data/edge_analysis9.md
A6: 5 | B6: Stock Market | D6: Compound | E6: raw | F6: Dividend Aristocrats (NOBL) | G6: 10.5 | H6: Annualized | I6: 0.02 | J6: 1 | K6: =1 -> 1 | L6: =I6 -> 0.02 | M6: =I6*7 -> 0.14 | N6: =I6*30 -> 0.6 | O6: =I6*365 -> 7.3 | P6: =I6*1825 -> 36.5 | Q6: =I6*3650 -> 73 | R6: =IF(D6="Linear",K6*J6*(G6/100),IF(I6>0,(1+((G6/100)*J6))^(1/(I6*365))-1,0)) -> 0.013771407 | S6: =IF(D6="Linear",L6*J6*(G6/100),(1+((G6/100)*J6))^(1/365)-1) -> 0.00027358628 | T6: =IF(D6="Linear",M6*J6*(G6/100),(1+((G6/100)*J6))^(7/365)-1) -> 0.0019166765 | U6: =IF(D6="Linear",N6*J6*(G6/100),(1+((G6/100)*J6))^(30/365)-1) -> 0.0082402312 | V6: =IF(D6="Linear",O6*J6*(G6/100),(1+((G6/100)*J6))-1) -> 0.105 | W6: =IF(D6="Linear",P6*J6*(G6/100),(1+((G6/100)*J6))^5-1) -> 0.64744677 | X6: =IF(D6="Linear",Q6*J6*(G6/100),(1+((G6/100)*J6))^10-1) -> 1.7140808 | Y6: Long-term allocation; roughly 5 portfolio decisions per year | Z6: /mnt/data/edge_analysis9.md
A7: 6 | B7: Stock Market | D7: Compound | E7: raw | F7: Total US Stock Market (VTI) | G7: 10.2 | H7: Annualized | I7: 0.02 | J7: 1 | K7: =1 -> 1 | L7: =I7 -> 0.02 | M7: =I7*7 -> 0.14 | N7: =I7*30 -> 0.6 | O7: =I7*365 -> 7.3 | P7: =I7*1825 -> 36.5 | Q7: =I7*3650 -> 73 | R7: =IF(D7="Linear",K7*J7*(G7/100),IF(I7>0,(1+((G7/100)*J7))^(1/(I7*365))-1,0)) -> 0.013393935 | S7: =IF(D7="Linear",L7*J7*(G7/100),(1+((G7/100)*J7))^(1/365)-1) -> 0.00026613599 | T7: =IF(D7="Linear",M7*J7*(G7/100),(1+((G7/100)*J7))^(7/365)-1) -> 0.00186444 | U7: =IF(D7="Linear",N7*J7*(G7/100),(1+((G7/100)*J7))^(30/365)-1) -> 0.0080149666 | V7: =IF(D7="Linear",O7*J7*(G7/100),(1+((G7/100)*J7))-1) -> 0.102 | W7: =IF(D7="Linear",P7*J7*(G7/100),(1+((G7/100)*J7))^5-1) -> 0.62520434 | X7: =IF(D7="Linear",Q7*J7*(G7/100),(1+((G7/100)*J7))^10-1) -> 1.6412891 | Y7: Long-term allocation; roughly 5 portfolio decisions per year | Z7: /mnt/data/edge_analysis9.md
A8: 7 | B8: Stock Market | D8: Compound | E8: raw | F8: S&P 500 Index (SPY/VOO) | G8: 10 | H8: Annualized | I8: 0.02 | J8: 1 | K8: =1 -> 1 | L8: =I8 -> 0.02 | M8: =I8*7 -> 0.14 | N8: =I8*30 -> 0.6 | O8: =I8*365 -> 7.3 | P8: =I8*1825 -> 36.5 | Q8: =I8*3650 -> 73 | R8: =IF(D8="Linear",K8*J8*(G8/100),IF(I8>0,(1+((G8/100)*J8))^(1/(I8*365))-1,0)) -> 0.013141793 | S8: =IF(D8="Linear",L8*J8*(G8/100),(1+((G8/100)*J8))^(1/365)-1) -> 0.00026115788 | T8: =IF(D8="Linear",M8*J8*(G8/100),(1+((G8/100)*J8))^(7/365)-1) -> 0.001829538 | U8: =IF(D8="Linear",N8*J8*(G8/100),(1+((G8/100)*J8))^(30/365)-1) -> 0.0078644772 | V8: =IF(D8="Linear",O8*J8*(G8/100),(1+((G8/100)*J8))-1) -> 0.1 | W8: =IF(D8="Linear",P8*J8*(G8/100),(1+((G8/100)*J8))^5-1) -> 0.61051 | X8: =IF(D8="Linear",Q8*J8*(G8/100),(1+((G8/100)*J8))^10-1) -> 1.5937425 | Y8: Long-term allocation; roughly 5 portfolio decisions per year | Z8: /mnt/data/edge_analysis9.md
A9: 8 | B9: Stock Market | D9: Compound | E9: raw | F9: S&P 500 Equal Weight (RSP) | G9: 10 | H9: Annualized | I9: 0.02 | J9: 1 | K9: =1 -> 1 | L9: =I9 -> 0.02 | M9: =I9*7 -> 0.14 | N9: =I9*30 -> 0.6 | O9: =I9*365 -> 7.3 | P9: =I9*1825 -> 36.5 | Q9: =I9*3650 -> 73 | R9: =IF(D9="Linear",K9*J9*(G9/100),IF(I9>0,(1+((G9/100)*J9))^(1/(I9*365))-1,0)) -> 0.013141793 | S9: =IF(D9="Linear",L9*J9*(G9/100),(1+((G9/100)*J9))^(1/365)-1) -> 0.00026115788 | T9: =IF(D9="Linear",M9*J9*(G9/100),(1+((G9/100)*J9))^(7/365)-1) -> 0.001829538 | U9: =IF(D9="Linear",N9*J9*(G9/100),(1+((G9/100)*J9))^(30/365)-1) -> 0.0078644772 | V9: =IF(D9="Linear",O9*J9*(G9/100),(1+((G9/100)*J9))-1) -> 0.1 | W9: =IF(D9="Linear",P9*J9*(G9/100),(1+((G9/100)*J9))^5-1) -> 0.61051 | X9: =IF(D9="Linear",Q9*J9*(G9/100),(1+((G9/100)*J9))^10-1) -> 1.5937425 | Y9: Long-term allocation; roughly 5 portfolio decisions per year | Z9: /mnt/data/edge_analysis9.md
A10: 9 | B10: Stock Market | D10: Compound | E10: raw | F10: Dow Jones Industrial (DIA) | G10: 9.5 | H10: Annualized | I10: 0.02 | J10: 1 | K10: =1 -> 1 | L10: =I10 -> 0.02 | M10: =I10*7 -> 0.14 | N10: =I10*30 -> 0.6 | O10: =I10*365 -> 7.3 | P10: =I10*1825 -> 36.5 | Q10: =I10*3650 -> 73 | R10: =IF(D10="Linear",K10*J10*(G10/100),IF(I10>0,(1+((G10/100)*J10))^(1/(I10*365))-1,0)) -> 0.012509704 | S10: =IF(D10="Linear",L10*J10*(G10/100),(1+((G10/100)*J10))^(1/365)-1) -> 0.00024867301 | T10: =IF(D10="Linear",M10*J10*(G10/100),(1+((G10/100)*J10))^(7/365)-1) -> 0.0017420102 | U10: =IF(D10="Linear",N10*J10*(G10/100),(1+((G10/100)*J10))^(30/365)-1) -> 0.0074871523 | V10: =IF(D10="Linear",O10*J10*(G10/100),(1+((G10/100)*J10))-1) -> 0.095 | W10: =IF(D10="Linear",P10*J10*(G10/100),(1+((G10/100)*J10))^5-1) -> 0.57423874 | X10: =IF(D10="Linear",Q10*J10*(G10/100),(1+((G10/100)*J10))^10-1) -> 1.4782276 | Y10: Long-term allocation; roughly 5 portfolio decisions per year | Z10: /mnt/data/edge_analysis9.md
A11: 10 | B11: Stock Market | D11: Compound | E11: raw | F11: S&P 500 Value (IVE) | G11: 9.5 | H11: Annualized | I11: 0.02 | J11: 1 | K11: =1 -> 1 | L11: =I11 -> 0.02 | M11: =I11*7 -> 0.14 | N11: =I11*30 -> 0.6 | O11: =I11*365 -> 7.3 | P11: =I11*1825 -> 36.5 | Q11: =I11*3650 -> 73 | R11: =IF(D11="Linear",K11*J11*(G11/100),IF(I11>0,(1+((G11/100)*J11))^(1/(I11*365))-1,0)) -> 0.012509704 | S11: =IF(D11="Linear",L11*J11*(G11/100),(1+((G11/100)*J11))^(1/365)-1) -> 0.00024867301 | T11: =IF(D11="Linear",M11*J11*(G11/100),(1+((G11/100)*J11))^(7/365)-1) -> 0.0017420102 | U11: =IF(D11="Linear",N11*J11*(G11/100),(1+((G11/100)*J11))^(30/365)-1) -> 0.0074871523 | V11: =IF(D11="Linear",O11*J11*(G11/100),(1+((G11/100)*J11))-1) -> 0.095 | W11: =IF(D11="Linear",P11*J11*(G11/100),(1+((G11/100)*J11))^5-1) -> 0.57423874 | X11: =IF(D11="Linear",Q11*J11*(G11/100),(1+((G11/100)*J11))^10-1) -> 1.4782276 | Y11: Long-term allocation; roughly 5 portfolio decisions per year | Z11: /mnt/data/edge_analysis9.md
A12: 11 | B12: Stock Market | D12: Compound | E12: raw | F12: Russell 2000 Small Cap (IWM) | G12: 8.5 | H12: Annualized | I12: 0.02 | J12: 1 | K12: =1 -> 1 | L12: =I12 -> 0.02 | M12: =I12*7 -> 0.14 | N12: =I12*30 -> 0.6 | O12: =I12*365 -> 7.3 | P12: =I12*1825 -> 36.5 | Q12: =I12*3650 -> 73 | R12: =IF(D12="Linear",K12*J12*(G12/100),IF(I12>0,(1+((G12/100)*J12))^(1/(I12*365))-1,0)) -> 0.011238018 | S12: =IF(D12="Linear",L12*J12*(G12/100),(1+((G12/100)*J12))^(1/365)-1) -> 0.00022353179 | T12: =IF(D12="Linear",M12*J12*(G12/100),(1+((G12/100)*J12))^(7/365)-1) -> 0.0015657722 | U12: =IF(D12="Linear",N12*J12*(G12/100),(1+((G12/100)*J12))^(30/365)-1) -> 0.0067277346 | V12: =IF(D12="Linear",O12*J12*(G12/100),(1+((G12/100)*J12))-1) -> 0.085 | W12: =IF(D12="Linear",P12*J12*(G12/100),(1+((G12/100)*J12))^5-1) -> 0.50365669 | X12: =IF(D12="Linear",Q12*J12*(G12/100),(1+((G12/100)*J12))^10-1) -> 1.2609834 | Y12: Long-term allocation; roughly 5 portfolio decisions per year | Z12: /mnt/data/edge_analysis9.md
A13: 12 | B13: Stock Market | D13: Compound | E13: raw | F13: REIT Index ETF (VNQ) | G13: 8 | H13: Annualized | I13: 0.02 | J13: 1 | K13: =1 -> 1 | L13: =I13 -> 0.02 | M13: =I13*7 -> 0.14 | N13: =I13*30 -> 0.6 | O13: =I13*365 -> 7.3 | P13: =I13*1825 -> 36.5 | Q13: =I13*3650 -> 73 | R13: =IF(D13="Linear",K13*J13*(G13/100),IF(I13>0,(1+((G13/100)*J13))^(1/(I13*365))-1,0)) -> 0.010598377 | S13: =IF(D13="Linear",L13*J13*(G13/100),(1+((G13/100)*J13))^(1/365)-1) -> 0.0002108744 | T13: =IF(D13="Linear",M13*J13*(G13/100),(1+((G13/100)*J13))^(7/365)-1) -> 0.0014770549 | U13: =IF(D13="Linear",N13*J13*(G13/100),(1+((G13/100)*J13))^(30/365)-1) -> 0.0063456137 | V13: =IF(D13="Linear",O13*J13*(G13/100),(1+((G13/100)*J13))-1) -> 0.08 | W13: =IF(D13="Linear",P13*J13*(G13/100),(1+((G13/100)*J13))^5-1) -> 0.46932808 | X13: =IF(D13="Linear",Q13*J13*(G13/100),(1+((G13/100)*J13))^10-1) -> 1.158925 | Y13: Long-term allocation; roughly 5 portfolio decisions per year | Z13: /mnt/data/edge_analysis9.md
... A72: 10 | B72: Cryptocurrency | D72: Compound | E72: tax | F72: Ethereum After LTCG Tax (20%) | G72: 8 | H72: Annualized | I72: 0.05 | J72: 0.7 | K72: =1 -> 1 | L72: =I72 -> 0.05 | M72: =I72*7 -> 0.35 | N72: =I72*30 -> 1.5 | O72: =I72*365 -> 18.25 | P72: =I72*1825 -> 91.25 | Q72: =I72*3650 -> 182.5 | R72: =IF(D72="Linear",K72*J72*(G72/100),IF(I72>0,(1+((G72/100)*J72))^(1/(I72*365))-1,0)) -> 0.0029901155 | S72: =IF(D72="Linear",L72*J72*(G72/100),(1+((G72/100)*J72))^(1/365)-1) -> 0.00014929384 | T72: =IF(D72="Linear",M72*J72*(G72/100),(1+((G72/100)*J72))^(7/365)-1) -> 0.0010455251 | U72: =IF(D72="Linear",N72*J72*(G72/100),(1+((G72/100)*J72))^(30/365)-1) -> 0.0044885244 | V72: =IF(D72="Linear",O72*J72*(G72/100),(1+((G72/100)*J72))-1) -> 0.056 | W72: =IF(D72="Linear",P72*J72*(G72/100),(1+((G72/100)*J72))^5-1) -> 0.31316588 | X72: =IF(D72="Linear",Q72*J72*(G72/100),(1+((G72/100)*J72))^10-1) -> 0.72440464 | Y72: Core crypto allocation; moderate turnover | Z72: /mnt/data/edge_analysis9.md
A73: 1 | B73: Options & Derivatives | C73: Compound Entries | D73: Compound | E73: raw | F73: Iron Condor Selling | G73: 10 | H73: Annualized | I73: 0.05 | J73: 0.25 | K73: =1 -> 1 | L73: =I73 -> 0.05 | M73: =I73*7 -> 0.35 | N73: =I73*30 -> 1.5 | O73: =I73*365 -> 18.25 | P73: =I73*1825 -> 91.25 | Q73: =I73*3650 -> 182.5 | R73: =IF(D73="Linear",K73*J73*(G73/100),IF(I73>0,(1+((G73/100)*J73))^(1/(I73*365))-1,0)) -> 0.0013539356 | S73: =IF(D73="Linear",L73*J73*(G73/100),(1+((G73/100)*J73))^(1/365)-1) -> 6.7653282e-05 | T73: =IF(D73="Linear",M73*J73*(G73/100),(1+((G73/100)*J73))^(7/365)-1) -> 0.0004736691 | U73: =IF(D73="Linear",N73*J73*(G73/100),(1+((G73/100)*J73))^(30/365)-1) -> 0.0020315907 | V73: =IF(D73="Linear",O73*J73*(G73/100),(1+((G73/100)*J73))-1) -> 0.025 | W73: =IF(D73="Linear",P73*J73*(G73/100),(1+((G73/100)*J73))^5-1) -> 0.13140821 | X73: =IF(D73="Linear",Q73*J73*(G73/100),(1+((G73/100)*J73))^10-1) -> 0.28008454 | Y73: Monthly premium-selling cycle; defined-risk sizing | Z73: /mnt/data/edge_analysis9.md
A74: 2 | B74: Options & Derivatives | C74: Compound Entries | D74: Compound | E74: raw | F74: Cash-Secured Put Selling | G74: 8 | H74: Annualized | I74: 0.03 | J74: 0.5 | K74: =1 -> 1 | L74: =I74 -> 0.03 | M74: =I74*7 -> 0.21 | N74: =I74*30 -> 0.9 | O74: =I74*365 -> 10.95 | P74: =I74*1825 -> 54.75 | Q74: =I74*3650 -> 109.5 | R74: =IF(D74="Linear",K74*J74*(G74/100),IF(I74>0,(1+((G74/100)*J74))^(1/(I74*365))-1,0)) -> 0.0035882226 | S74: =IF(D74="Linear",L74*J74*(G74/100),(1+((G74/100)*J74))^(1/365)-1) -> 0.00010745978 | T74: =IF(D74="Linear",M74*J74*(G74/100),(1+((G74/100)*J74))^(7/365)-1) -> 0.00075246102 | U74: =IF(D74="Linear",N74*J74*(G74/100),(1+((G74/100)*J74))^(30/365)-1) -> 0.0032288217 | V74: =IF(D74="Linear",O74*J74*(G74/100),(1+((G74/100)*J74))-1) -> 0.04 | W74: =IF(D74="Linear",P74*J74*(G74/100),(1+((G74/100)*J74))^5-1) -> 0.2166529 | X74: =IF(D74="Linear",Q74*J74*(G74/100),(1+((G74/100)*J74))^10-1) -> 0.48024428 | Y74: Lower-frequency options income strategy | Z74: /mnt/data/edge_analysis9.md
A75: 3 | B75: Options & Derivatives | C75: Compound Entries | D75: Compound | E75: raw | F75: Covered Call Writing | G75: 7 | H75: Annualized | I75: 0.03 | J75: 0.6 | K75: =1 -> 1 | L75: =I75 -> 0.03 | M75: =I75*7 -> 0.21 | N75: =I75*30 -> 0.9 | O75: =I75*365 -> 10.95 | P75: =I75*1825 -> 54.75 | Q75: =I75*3650 -> 109.5 | R75: =IF(D75="Linear",K75*J75*(G75/100),IF(I75>0,(1+((G75/100)*J75))^(1/(I75*365))-1,0)) -> 0.0037643224 | S75: =IF(D75="Linear",L75*J75*(G75/100),(1+((G75/100)*J75))^(1/365)-1) -> 0.00011272401 | T75: =IF(D75="Linear",M75*J75*(G75/100),(1+((G75/100)*J75))^(7/365)-1) -> 0.00078933493 | U75: =IF(D75="Linear",N75*J75*(G75/100),(1+((G75/100)*J75))^(30/365)-1) -> 0.0033872534 | V75: =IF(D75="Linear",O75*J75*(G75/100),(1+((G75/100)*J75))-1) -> 0.042 | W75: =IF(D75="Linear",P75*J75*(G75/100),(1+((G75/100)*J75))^5-1) -> 0.22839657 | X75: =IF(D75="Linear",Q75*J75*(G75/100),(1+((G75/100)*J75))^10-1) -> 0.50895813 | Y75: Overlay strategy on existing holdings | Z75: /mnt/data/edge_analysis9.md
A76: 4 | B76: Options & Derivatives | C76: Compound Entries | D76: Compound | E76: raw | F76: Managed Futures / CTA | G76: 3 | H76: Annualized | I76: 0.02 | J76: 0.5 | K76: =1 -> 1 | L76: =I76 -> 0.02 | M76: =I76*7 -> 0.14 | N76: =I76*30 -> 0.6 | O76: =I76*365 -> 7.3 | P76: =I76*1825 -> 36.5 | Q76: =I76*3650 -> 73 | R76: =IF(D76="Linear",K76*J76*(G76/100),IF(I76>0,(1+((G76/100)*J76))^(1/(I76*365))-1,0)) -> 0.0020416172 | S76: =IF(D76="Linear",L76*J76*(G76/100),(1+((G76/100)*J76))^(1/365)-1) -> 4.0791551e-05 | T76: =IF(D76="Linear",M76*J76*(G76/100),(1+((G76/100)*J76))^(7/365)-1) -> 0.0002855758 | U76: =IF(D76="Linear",N76*J76*(G76/100),(1+((G76/100)*J76))^(30/365)-1) -> 0.0012244706 | V76: =IF(D76="Linear",O76*J76*(G76/100),(1+((G76/100)*J76))-1) -> 0.015 | W76: =IF(D76="Linear",P76*J76*(G76/100),(1+((G76/100)*J76))^5-1) -> 0.077284004 | X76: =IF(D76="Linear",Q76*J76*(G76/100),(1+((G76/100)*J76))^10-1) -> 0.16054083 | Y76: Managed futures / systematic alternatives | Z76: /mnt/data/edge_analysis9.md
A77: 11 | B77: Options & Derivatives | C77: Compound Entries | D77: Compound | E77: tax | F77: Iron Condor After STCG Tax (37%) | G77: 6.3 | H77: Annualized | I77: 0.05 | J77: 0.25 | K77: =1 -> 1 | L77: =I77 -> 0.05 | M77: =I77*7 -> 0.35 | N77: =I77*30 -> 1.5 | O77: =I77*365 -> 18.25 | P77: =I77*1825 -> 91.25 | Q77: =I77*3650 -> 182.5 | R77: =IF(D77="Linear",K77*J77*(G77/100),IF(I77>0,(1+((G77/100)*J77))^(1/(I77*365))-1,0)) -> 0.00085665471 | S77: =IF(D77="Linear",L77*J77*(G77/100),(1+((G77/100)*J77))^(1/365)-1) -> 4.2815316e-05 | T77: =IF(D77="Linear",M77*J77*(G77/100),(1+((G77/100)*J77))^(7/365)-1) -> 0.00029974571 | U77: =IF(D77="Linear",N77*J77*(G77/100),(1+((G77/100)*J77))^(30/365)-1) -> 0.0012852572 | V77: =IF(D77="Linear",O77*J77*(G77/100),(1+((G77/100)*J77))-1) -> 0.01575 | W77: =IF(D77="Linear",P77*J77*(G77/100),(1+((G77/100)*J77))^5-1) -> 0.081270003 | X77: =IF(D77="Linear",Q77*J77*(G77/100),(1+((G77/100)*J77))^10-1) -> 0.16914482 | Y77: Monthly premium-selling cycle; defined-risk sizing | Z77: /mnt/data/edge_analysis9.md
A78: 12 | B78: Options & Derivatives | C78: Compound Entries | D78: Compound | E78: tax | F78: Cash-Secured Put After STCG Tax (37%) | G78: 5.04 | H78: Annualized | I78: 0.03 | J78: 0.5 | K78: =1 -> 1 | L78: =I78 -> 0.03 | M78: =I78*7 -> 0.21 | N78: =I78*30 -> 0.9 | O78: =I78*365 -> 10.95 | P78: =I78*1825 -> 54.75 | Q78: =I78*3650 -> 109.5 | R78: =IF(D78="Linear",K78*J78*(G78/100),IF(I78>0,(1+((G78/100)*J78))^(1/(I78*365))-1,0)) -> 0.0022754356 | S78: =IF(D78="Linear",L78*J78*(G78/100),(1+((G78/100)*J78))^(1/365)-1) -> 6.8187847e-05 | T78: =IF(D78="Linear",M78*J78*(G78/100),(1+((G78/100)*J78))^(7/365)-1) -> 0.00047741258 | U78: =IF(D78="Linear",N78*J78*(G78/100),(1+((G78/100)*J78))^(30/365)-1) -> 0.0020476593 | V78: =IF(D78="Linear",O78*J78*(G78/100),(1+((G78/100)*J78))-1) -> 0.0252 | W78: =IF(D78="Linear",P78*J78*(G78/100),(1+((G78/100)*J78))^5-1) -> 0.13251246 | X78: =IF(D78="Linear",Q78*J78*(G78/100),(1+((G78/100)*J78))^10-1) -> 0.28258446 | Y78: Lower-frequency options income strategy | Z78: /mnt/data/edge_analysis9.md
A79: 13 | B79: Options & Derivatives | C79: Compound Entries | D79: Compound | E79: tax | F79: Covered Call After STCG Tax (37%) | G79: 4.41 | H79: Annualized | I79: 0.03 | J79: 0.6 | K79: =1 -> 1 | L79: =I79 -> 0.03 | M79: =I79*7 -> 0.21 | N79: =I79*30 -> 0.9 | O79: =I79*365 -> 10.95 | P79: =I79*1825 -> 54.75 | Q79: =I79*3650 -> 109.5 | R79: =IF(D79="Linear",K79*J79*(G79/100),IF(I79>0,(1+((G79/100)*J79))^(1/(I79*365))-1,0)) -> 0.0023878683 | S79: =IF(D79="Linear",L79*J79*(G79/100),(1+((G79/100)*J79))^(1/365)-1) -> 7.1553216e-05 | T79: =IF(D79="Linear",M79*J79*(G79/100),(1+((G79/100)*J79))^(7/365)-1) -> 0.00050098004 | U79: =IF(D79="Linear",N79*J79*(G79/100),(1+((G79/100)*J79))^(30/365)-1) -> 0.0021488251 | V79: =IF(D79="Linear",O79*J79*(G79/100),(1+((G79/100)*J79))-1) -> 0.02646 | W79: =IF(D79="Linear",P79*J79*(G79/100),(1+((G79/100)*J79))^5-1) -> 0.13948903 | X79: =IF(D79="Linear",Q79*J79*(G79/100),(1+((G79/100)*J79))^10-1) -> 0.29843526 | Y79: Overlay strategy on existing holdings | Z79: /mnt/data/edge_analysis9.md
A80: 14 | B80: Options & Derivatives | C80: Compound Entries | D80: Compound | E80: tax | F80: Managed Futures After 60/40 Tax (26.8%) | G80: 2.2 | H80: Annualized | I80: 0.02 | J80: 0.5 | K80: =1 -> 1 | L80: =I80 -> 0.02 | M80: =I80*7 -> 0.14 | N80: =I80*30 -> 0.6 | O80: =I80*365 -> 7.3 | P80: =I80*1825 -> 36.5 | Q80: =I80*3650 -> 73 | R80: =IF(D80="Linear",K80*J80*(G80/100),IF(I80>0,(1+((G80/100)*J80))^(1/(I80*365))-1,0)) -> 0.0014997454 | S80: =IF(D80="Linear",L80*J80*(G80/100),(1+((G80/100)*J80))^(1/365)-1) -> 2.9972888e-05 | T80: =IF(D80="Linear",M80*J80*(G80/100),(1+((G80/100)*J80))^(7/365)-1) -> 0.00020982908 | U80: =IF(D80="Linear",N80*J80*(G80/100),(1+((G80/100)*J80))^(30/365)-1) -> 0.00089957753 | V80: =IF(D80="Linear",O80*J80*(G80/100),(1+((G80/100)*J80))-1) -> 0.011 | W80: =IF(D80="Linear",P80*J80*(G80/100),(1+((G80/100)*J80))^5-1) -> 0.056223383 | X80: =IF(D80="Linear",Q80*J80*(G80/100),(1+((G80/100)*J80))^10-1) -> 0.11560784 | Y80: Managed futures / systematic alternatives | Z80: /mnt/data/edge_analysis9.md
A81: 5 | B81: Options & Derivatives | C81: Linear Entries | D81: Linear | E81: raw | F81: Commodity Futures (Retail) | G81: -8 | H81: Per Decision | I81: 3 | J81: 0.03 | K81: =1 -> 1 | L81: =I81 -> 3 | M81: =I81*7 -> 21 | N81: =I81*30 -> 90 | O81: =I81*365 -> 1095 | P81: =I81*1825 -> 5475 | Q81: =I81*3650 -> 10950 | R81: =IF(D81="Linear",K81*J81*(G81/100),IF(I81>0,(1+((G81/100)*J81))^(1/(I81*365))-1,0)) -> -0.0024 | S81: =IF(D81="Linear",L81*J81*(G81/100),(1+((G81/100)*J81))^(1/365)-1) -> -0.0072 | T81: =IF(D81="Linear",M81*J81*(G81/100),(1+((G81/100)*J81))^(7/365)-1) -> -0.0504 | U81: =IF(D81="Linear",N81*J81*(G81/100),(1+((G81/100)*J81))^(30/365)-1) -> -0.216 | V81: =IF(D81="Linear",O81*J81*(G81/100),(1+((G81/100)*J81))-1) -> -2.628 | W81: =IF(D81="Linear",P81*J81*(G81/100),(1+((G81/100)*J81))^5-1) -> -13.14 | X81: =IF(D81="Linear",Q81*J81*(G81/100),(1+((G81/100)*J81))^10-1) -> -26.28 | Y81: Retail futures speculation | Z81: /mnt/data/edge_analysis9.md
A82: 6 | B82: Options & Derivatives | C82: Linear Entries | D82: Linear | E82: raw | F82: ATM Options Buying (30-Day) | G82: -15 | H82: Per Decision | I82: 1 | J82: 0.03 | K82: =1 -> 1 | L82: =I82 -> 1 | M82: =I82*7 -> 7 | N82: =I82*30 -> 30 | O82: =I82*365 -> 365 | P82: =I82*1825 -> 1825 | Q82: =I82*3650 -> 3650 | R82: =IF(D82="Linear",K82*J82*(G82/100),IF(I82>0,(1+((G82/100)*J82))^(1/(I82*365))-1,0)) -> -0.0045 | S82: =IF(D82="Linear",L82*J82*(G82/100),(1+((G82/100)*J82))^(1/365)-1) -> -0.0045 | T82: =IF(D82="Linear",M82*J82*(G82/100),(1+((G82/100)*J82))^(7/365)-1) -> -0.0315 | U82: =IF(D82="Linear",N82*J82*(G82/100),(1+((G82/100)*J82))^(30/365)-1) -> -0.135 | V82: =IF(D82="Linear",O82*J82*(G82/100),(1+((G82/100)*J82))-1) -> -1.6425 | W82: =IF(D82="Linear",P82*J82*(G82/100),(1+((G82/100)*J82))^5-1) -> -8.2125 | X82: =IF(D82="Linear",Q82*J82*(G82/100),(1+((G82/100)*J82))^10-1) -> -16.425 | Y82: Lower-frequency directional option bets | Z82: /mnt/data/edge_analysis9.md
A83: 7 | B83: Options & Derivatives | C83: Linear Entries | D83: Linear | E83: raw | F83: Leveraged Futures Day Trading | G83: -25 | H83: Per Decision | I83: 8 | J83: 0.02 | K83: =1 -> 1 | L83: =I83 -> 8 | M83: =I83*7 -> 56 | N83: =I83*30 -> 240 | O83: =I83*365 -> 2920 | P83: =I83*1825 -> 14600 | Q83: =I83*3650 -> 29200 | R83: =IF(D83="Linear",K83*J83*(G83/100),IF(I83>0,(1+((G83/100)*J83))^(1/(I83*365))-1,0)) -> -0.005 | S83: =IF(D83="Linear",L83*J83*(G83/100),(1+((G83/100)*J83))^(1/365)-1) -> -0.04 | T83: =IF(D83="Linear",M83*J83*(G83/100),(1+((G83/100)*J83))^(7/365)-1) -> -0.28 | U83: =IF(D83="Linear",N83*J83*(G83/100),(1+((G83/100)*J83))^(30/365)-1) -> -1.2 | V83: =IF(D83="Linear",O83*J83*(G83/100),(1+((G83/100)*J83))-1) -> -14.6 | W83: =IF(D83="Linear",P83*J83*(G83/100),(1+((G83/100)*J83))^5-1) -> -73 | X83: =IF(D83="Linear",Q83*J83*(G83/100),(1+((G83/100)*J83))^10-1) -> -146 | Y83: Intraday leveraged trading | Z83: /mnt/data/edge_analysis9.md
A84: 8 | B84: Options & Derivatives | C84: Linear Entries | D84: Linear | E84: raw | F84: OTM Options Buying (30-Day) | G84: -35 | H84: Per Decision | I84: 2 | J84: 0.02 | K84: =1 -> 1 | L84: =I84 -> 2 | M84: =I84*7 -> 14 | N84: =I84*30 -> 60 | O84: =I84*365 -> 730 | P84: =I84*1825 -> 3650 | Q84: =I84*3650 -> 7300 | R84: =IF(D84="Linear",K84*J84*(G84/100),IF(I84>0,(1+((G84/100)*J84))^(1/(I84*365))-1,0)) -> -0.007 | S84: =IF(D84="Linear",L84*J84*(G84/100),(1+((G84/100)*J84))^(1/365)-1) -> -0.014 | T84: =IF(D84="Linear",M84*J84*(G84/100),(1+((G84/100)*J84))^(7/365)-1) -> -0.098 | U84: =IF(D84="Linear",N84*J84*(G84/100),(1+((G84/100)*J84))^(30/365)-1) -> -0.42 | V84: =IF(D84="Linear",O84*J84*(G84/100),(1+((G84/100)*J84))-1) -> -5.11 | W84: =IF(D84="Linear",P84*J84*(G84/100),(1+((G84/100)*J84))^5-1) -> -25.55 | X84: =IF(D84="Linear",Q84*J84*(G84/100),(1+((G84/100)*J84))^10-1) -> -51.1 | Y84: Short-dated speculative option buying | Z84: /mnt/data/edge_analysis9.md
... A86: 10 | B86: Options & Derivatives | C86: Linear Entries | D86: Linear | E86: raw | F86: Deep OTM Weekly Options | G86: -60 | H86: Per Decision | I86: 2 | J86: 0.02 | K86: =1 -> 1 | L86: =I86 -> 2 | M86: =I86*7 -> 14 | N86: =I86*30 -> 60 | O86: =I86*365 -> 730 | P86: =I86*1825 -> 3650 | Q86: =I86*3650 -> 7300 | R86: =IF(D86="Linear",K86*J86*(G86/100),IF(I86>0,(1+((G86/100)*J86))^(1/(I86*365))-1,0)) -> -0.012 | S86: =IF(D86="Linear",L86*J86*(G86/100),(1+((G86/100)*J86))^(1/365)-1) -> -0.024 | T86: =IF(D86="Linear",M86*J86*(G86/100),(1+((G86/100)*J86))^(7/365)-1) -> -0.168 | U86: =IF(D86="Linear",N86*J86*(G86/100),(1+((G86/100)*J86))^(30/365)-1) -> -0.72 | V86: =IF(D86="Linear",O86*J86*(G86/100),(1+((G86/100)*J86))-1) -> -8.76 | W86: =IF(D86="Linear",P86*J86*(G86/100),(1+((G86/100)*J86))^5-1) -> -43.8 | X86: =IF(D86="Linear",Q86*J86*(G86/100),(1+((G86/100)*J86))^10-1) -> -87.6 | Y86: Short-dated speculative option buying | Z86: /mnt/data/edge_analysis9.md
A87: 1 | B87: Active Trading | D87: Compound | E87: raw | F87: Systematic Trend Following | G87: 5 | H87: Annualized | I87: 0.3 | J87: 0.5 | K87: =1 -> 1 | L87: =I87 -> 0.3 | M87: =I87*7 -> 2.1 | N87: =I87*30 -> 9 | O87: =I87*365 -> 109.5 | P87: =I87*1825 -> 547.5 | Q87: =I87*3650 -> 1095 | R87: =IF(D87="Linear",K87*J87*(G87/100),IF(I87>0,(1+((G87/100)*J87))^(1/(I87*365))-1,0)) -> 0.00022552874 | S87: =IF(D87="Linear",L87*J87*(G87/100),(1+((G87/100)*J87))^(1/365)-1) -> 6.7653282e-05 | T87: =IF(D87="Linear",M87*J87*(G87/100),(1+((G87/100)*J87))^(7/365)-1) -> 0.0004736691 | U87: =IF(D87="Linear",N87*J87*(G87/100),(1+((G87/100)*J87))^(30/365)-1) -> 0.0020315907 | V87: =IF(D87="Linear",O87*J87*(G87/100),(1+((G87/100)*J87))-1) -> 0.025 | W87: =IF(D87="Linear",P87*J87*(G87/100),(1+((G87/100)*J87))^5-1) -> 0.13140821 | X87: =IF(D87="Linear",Q87*J87*(G87/100),(1+((G87/100)*J87))^10-1) -> 0.28008454 | Y87: Systematic trend program; moderate turnover | Z87: /mnt/data/edge_analysis9.md
A88: 2 | B88: Active Trading | D88: Compound | E88: raw | F88: Social/Copy Trading (Retail) | G88: -12 | H88: Annualized | I88: 2 | J88: 0.05 | K88: =1 -> 1 | L88: =I88 -> 2 | M88: =I88*7 -> 14 | N88: =I88*30 -> 60 | O88: =I88*365 -> 730 | P88: =I88*1825 -> 3650 | Q88: =I88*3650 -> 7300 | R88: =IF(D88="Linear",K88*J88*(G88/100),IF(I88>0,(1+((G88/100)*J88))^(1/(I88*365))-1,0)) -> -8.2439007e-06 | S88: =IF(D88="Linear",L88*J88*(G88/100),(1+((G88/100)*J88))^(1/365)-1) -> -1.6487733e-05 | T88: =IF(D88="Linear",M88*J88*(G88/100),(1+((G88/100)*J88))^(7/365)-1) -> -0.00011540843 | U88: =IF(D88="Linear",N88*J88*(G88/100),(1+((G88/100)*J88))^(30/365)-1) -> -0.00049451377 | V88: =IF(D88="Linear",O88*J88*(G88/100),(1+((G88/100)*J88))-1) -> -0.006 | W88: =IF(D88="Linear",P88*J88*(G88/100),(1+((G88/100)*J88))^5-1) -> -0.029642154 | X88: =IF(D88="Linear",Q88*J88*(G88/100),(1+((G88/100)*J88))^10-1) -> -0.05840565 | Y88: Moderate active-trading cadence | Z88: /mnt/data/edge_analysis9.md
A89: 3 | B89: Active Trading | D89: Compound | E89: raw | F89: Momentum Trading (Retail) | G89: -18 | H89: Annualized | I89: 2 | J89: 0.05 | K89: =1 -> 1 | L89: =I89 -> 2 | M89: =I89*7 -> 14 | N89: =I89*30 -> 60 | O89: =I89*365 -> 730 | P89: =I89*1825 -> 3650 | Q89: =I89*3650 -> 7300 | R89: =IF(D89="Linear",K89*J89*(G89/100),IF(I89>0,(1+((G89/100)*J89))^(1/(I89*365))-1,0)) -> -1.2384505e-05 | S89: =IF(D89="Linear",L89*J89*(G89/100),(1+((G89/100)*J89))^(1/365)-1) -> -2.4768857e-05 | T89: =IF(D89="Linear",M89*J89*(G89/100),(1+((G89/100)*J89))^(7/365)-1) -> -0.00017336911 | U89: =IF(D89="Linear",N89*J89*(G89/100),(1+((G89/100)*J89))^(30/365)-1) -> -0.00074279889 | V89: =IF(D89="Linear",O89*J89*(G89/100),(1+((G89/100)*J89))-1) -> -0.009 | W89: =IF(D89="Linear",P89*J89*(G89/100),(1+((G89/100)*J89))^5-1) -> -0.044197257 | X89: =IF(D89="Linear",Q89*J89*(G89/100),(1+((G89/100)*J89))^10-1) -> -0.086441117 | Y89: Moderate active-trading cadence | Z89: /mnt/data/edge_analysis9.md
A90: 4 | B90: Active Trading | D90: Compound | E90: raw | F90: Retail Forex Trading | G90: -25 | H90: Annualized | I90: 6 | J90: 0.03 | K90: =1 -> 1 | L90: =I90 -> 6 | M90: =I90*7 -> 42 | N90: =I90*30 -> 180 | O90: =I90*365 -> 2190 | P90: =I90*1825 -> 10950 | Q90: =I90*3650 -> 21900 | R90: =IF(D90="Linear",K90*J90*(G90/100),IF(I90>0,(1+((G90/100)*J90))^(1/(I90*365))-1,0)) -> -3.4375587e-06 | S90: =IF(D90="Linear",L90*J90*(G90/100),(1+((G90/100)*J90))^(1/365)-1) -> -2.0625175e-05 | T90: =IF(D90="Linear",M90*J90*(G90/100),(1+((G90/100)*J90))^(7/365)-1) -> -0.00014436729 | U90: =IF(D90="Linear",N90*J90*(G90/100),(1+((G90/100)*J90))^(30/365)-1) -> -0.00061857023 | V90: =IF(D90="Linear",O90*J90*(G90/100),(1+((G90/100)*J90))-1) -> -0.0075 | W90: =IF(D90="Linear",P90*J90*(G90/100),(1+((G90/100)*J90))^5-1) -> -0.036941703 | X90: =IF(D90="Linear",Q90*J90*(G90/100),(1+((G90/100)*J90))^10-1) -> -0.072518716 | Y90: Frequent leveraged trading | Z90: /mnt/data/edge_analysis9.md
A91: 5 | B91: Active Trading | D91: Compound | E91: raw | F91: CFD Trading (Retail, Leveraged) | G91: -28 | H91: Annualized | I91: 6 | J91: 0.03 | K91: =1 -> 1 | L91: =I91 -> 6 | M91: =I91*7 -> 42 | N91: =I91*30 -> 180 | O91: =I91*365 -> 2190 | P91: =I91*1825 -> 10950 | Q91: =I91*3650 -> 21900 | R91: =IF(D91="Linear",K91*J91*(G91/100),IF(I91>0,(1+((G91/100)*J91))^(1/(I91*365))-1,0)) -> -3.8518094e-06 | S91: =IF(D91="Linear",L91*J91*(G91/100),(1+((G91/100)*J91))^(1/365)-1) -> -2.3110634e-05 | T91: =IF(D91="Linear",M91*J91*(G91/100),(1+((G91/100)*J91))^(7/365)-1) -> -0.00016176322 | U91: =IF(D91="Linear",N91*J91*(G91/100),(1+((G91/100)*J91))^(30/365)-1) -> -0.00069308673 | V91: =IF(D91="Linear",O91*J91*(G91/100),(1+((G91/100)*J91))-1) -> -0.0084 | W91: =IF(D91="Linear",P91*J91*(G91/100),(1+((G91/100)*J91))^5-1) -> -0.041300302 | X91: =IF(D91="Linear",Q91*J91*(G91/100),(1+((G91/100)*J91))^10-1) -> -0.080894889 | Y91: Frequent leveraged trading | Z91: /mnt/data/edge_analysis9.md
A92: 6 | B92: Active Trading | D92: Compound | E92: raw | F92: Retail Day Trading | G92: -30 | H92: Annualized | I92: 8 | J92: 0.03 | K92: =1 -> 1 | L92: =I92 -> 8 | M92: =I92*7 -> 56 | N92: =I92*30 -> 240 | O92: =I92*365 -> 2920 | P92: =I92*1825 -> 14600 | Q92: =I92*3650 -> 29200 | R92: =IF(D92="Linear",K92*J92*(G92/100),IF(I92>0,(1+((G92/100)*J92))^(1/(I92*365))-1,0)) -> -3.0961406e-06 | S92: =IF(D92="Linear",L92*J92*(G92/100),(1+((G92/100)*J92))^(1/365)-1) -> -2.4768857e-05 | T92: =IF(D92="Linear",M92*J92*(G92/100),(1+((G92/100)*J92))^(7/365)-1) -> -0.00017336911 | U92: =IF(D92="Linear",N92*J92*(G92/100),(1+((G92/100)*J92))^(30/365)-1) -> -0.00074279889 | V92: =IF(D92="Linear",O92*J92*(G92/100),(1+((G92/100)*J92))-1) -> -0.009 | W92: =IF(D92="Linear",P92*J92*(G92/100),(1+((G92/100)*J92))^5-1) -> -0.044197257 | X92: =IF(D92="Linear",Q92*J92*(G92/100),(1+((G92/100)*J92))^10-1) -> -0.086441117 | Y92: High-frequency retail trading | Z92: /mnt/data/edge_analysis9.md
A93: 7 | B93: Active Trading | D93: Compound | E93: raw | F93: Crypto Day Trading (Retail) | G93: -35 | H93: Annualized | I93: 8 | J93: 0.03 | K93: =1 -> 1 | L93: =I93 -> 8 | M93: =I93*7 -> 56 | N93: =I93*30 -> 240 | O93: =I93*365 -> 2920 | P93: =I93*1825 -> 14600 | Q93: =I93*3650 -> 29200 | R93: =IF(D93="Linear",K93*J93*(G93/100),IF(I93>0,(1+((G93/100)*J93))^(1/(I93*365))-1,0)) -> -3.6148955e-06 | S93: =IF(D93="Linear",L93*J93*(G93/100),(1+((G93/100)*J93))^(1/365)-1) -> -2.8918798e-05 | T93: =IF(D93="Linear",M93*J93*(G93/100),(1+((G93/100)*J93))^(7/365)-1) -> -0.00020241403 | U93: =IF(D93="Linear",N93*J93*(G93/100),(1+((G93/100)*J93))^(30/365)-1) -> -0.00086720025 | V93: =IF(D93="Linear",O93*J93*(G93/100),(1+((G93/100)*J93))-1) -> -0.0105 | W93: =IF(D93="Linear",P93*J93*(G93/100),(1+((G93/100)*J93))^5-1) -> -0.051409016 | X93: =IF(D93="Linear",Q93*J93*(G93/100),(1+((G93/100)*J93))^10-1) -> -0.10017514 | Y93: High-frequency retail trading | Z93: /mnt/data/edge_analysis9.md
A94: 8 | B94: Active Trading | D94: Compound | E94: raw | F94: Binary Options (Retail) | G94: -40 | H94: Annualized | I94: 8 | J94: 0.02 | K94: =1 -> 1 | L94: =I94 -> 8 | M94: =I94*7 -> 56 | N94: =I94*30 -> 240 | O94: =I94*365 -> 2920 | P94: =I94*1825 -> 14600 | Q94: =I94*3650 -> 29200 | R94: =IF(D94="Linear",K94*J94*(G94/100),IF(I94>0,(1+((G94/100)*J94))^(1/(I94*365))-1,0)) -> -2.7507399e-06 | S94: =IF(D94="Linear",L94*J94*(G94/100),(1+((G94/100)*J94))^(1/365)-1) -> -2.2005708e-05 | T94: =IF(D94="Linear",M94*J94*(G94/100),(1+((G94/100)*J94))^(7/365)-1) -> -0.00015402979 | U94: =IF(D94="Linear",N94*J94*(G94/100),(1+((G94/100)*J94))^(30/365)-1) -> -0.00065996063 | V94: =IF(D94="Linear",O94*J94*(G94/100),(1+((G94/100)*J94))-1) -> -0.008 | W94: =IF(D94="Linear",P94*J94*(G94/100),(1+((G94/100)*J94))^5-1) -> -0.0393651 | X94: =IF(D94="Linear",Q94*J94*(G94/100),(1+((G94/100)*J94))^10-1) -> -0.077180588 | Y94: High-frequency retail trading style | Z94: /mnt/data/edge_analysis9.md
A95: 9 | B95: Active Trading | D95: Compound | E95: tax | F95: Trend Following After STCG Tax (37%) | G95: 3.15 | H95: Annualized | I95: 2 | J95: 0.03 | K95: =1 -> 1 | L95: =I95 -> 2 | M95: =I95*7 -> 14 | N95: =I95*30 -> 60 | O95: =I95*365 -> 730 | P95: =I95*1825 -> 3650 | Q95: =I95*3650 -> 7300 | R95: =IF(D95="Linear",K95*J95*(G95/100),IF(I95>0,(1+((G95/100)*J95))^(1/(I95*365))-1,0)) -> 1.2939101e-06 | S95: =IF(D95="Linear",L95*J95*(G95/100),(1+((G95/100)*J95))^(1/365)-1) -> 2.5878219e-06 | T95: =IF(D95="Linear",M95*J95*(G95/100),(1+((G95/100)*J95))^(7/365)-1) -> 1.8114894e-05 | U95: =IF(D95="Linear",N95*J95*(G95/100),(1+((G95/100)*J95))^(30/365)-1) -> 7.763757e-05 | V95: =IF(D95="Linear",O95*J95*(G95/100),(1+((G95/100)*J95))-1) -> 0.000945 | W95: =IF(D95="Linear",P95*J95*(G95/100),(1+((G95/100)*J95))^5-1) -> 0.0047339387 | X95: =IF(D95="Linear",Q95*J95*(G95/100),(1+((G95/100)*J95))^10-1) -> 0.0094902876 | Y95: Active trading | Z95: /mnt/data/edge_analysis9.md
A96: 10 | B96: Active Trading | D96: Compound | E96: tax | F96: Day Trading After Income Tax (37%) | G96: -30 | H96: Annualized | I96: 8 | J96: 0.03 | K96: =1 -> 1 | L96: =I96 -> 8 | M96: =I96*7 -> 56 | N96: =I96*30 -> 240 | O96: =I96*365 -> 2920 | P96: =I96*1825 -> 14600 | Q96: =I96*3650 -> 29200 | R96: =IF(D96="Linear",K96*J96*(G96/100),IF(I96>0,(1+((G96/100)*J96))^(1/(I96*365))-1,0)) -> -3.0961406e-06 | S96: =IF(D96="Linear",L96*J96*(G96/100),(1+((G96/100)*J96))^(1/365)-1) -> -2.4768857e-05 | T96: =IF(D96="Linear",M96*J96*(G96/100),(1+((G96/100)*J96))^(7/365)-1) -> -0.00017336911 | U96: =IF(D96="Linear",N96*J96*(G96/100),(1+((G96/100)*J96))^(30/365)-1) -> -0.00074279889 | V96: =IF(D96="Linear",O96*J96*(G96/100),(1+((G96/100)*J96))-1) -> -0.009 | W96: =IF(D96="Linear",P96*J96*(G96/100),(1+((G96/100)*J96))^5-1) -> -0.044197257 | X96: =IF(D96="Linear",Q96*J96*(G96/100),(1+((G96/100)*J96))^10-1) -> -0.086441117 | Y96: High-frequency retail trading | Z96: /mnt/data/edge_analysis9.md
A97: 1 | B97: Collectibles | D97: Compound | E97: raw | F97: Vintage Sports Cards (PSA 10) | G97: 6 | H97: Annualized | I97: 0.005 | J97: 0.75 | K97: =1 -> 1 | L97: =I97 -> 0.005 | M97: =I97*7 -> 0.035 | N97: =I97*30 -> 0.15 | O97: =I97*365 -> 1.825 | P97: =I97*1825 -> 9.125 | Q97: =I97*3650 -> 18.25 | R97: =IF(D97="Linear",K97*J97*(G97/100),IF(I97>0,(1+((G97/100)*J97))^(1/(I97*365))-1,0)) -> 0.024412053 | S97: =IF(D97="Linear",L97*J97*(G97/100),(1+((G97/100)*J97))^(1/365)-1) -> 0.00012060148 | T97: =IF(D97="Linear",M97*J97*(G97/100),(1+((G97/100)*J97))^(7/365)-1) -> 0.00084451585 | U97: =IF(D97="Linear",N97*J97*(G97/100),(1+((G97/100)*J97))^(30/365)-1) -> 0.0036243784 | V97: =IF(D97="Linear",O97*J97*(G97/100),(1+((G97/100)*J97))-1) -> 0.045 | W97: =IF(D97="Linear",P97*J97*(G97/100),(1+((G97/100)*J97))^5-1) -> 0.24618194 | X97: =IF(D97="Linear",Q97*J97*(G97/100),(1+((G97/100)*J97))^10-1) -> 0.55296942 | Y97: Illiquid alternative asset; low turnover | Z97: /mnt/data/edge_analysis9.md
A98: 2 | B98: Collectibles | D98: Compound | E98: raw | F98: Fine Art (Blue Chip / Old Masters) | G98: 5 | H98: Annualized | I98: 0.005 | J98: 0.75 | K98: =1 -> 1 | L98: =I98 -> 0.005 | M98: =I98*7 -> 0.035 | N98: =I98*30 -> 0.15 | O98: =I98*365 -> 1.825 | P98: =I98*1825 -> 9.125 | Q98: =I98*3650 -> 18.25 | R98: =IF(D98="Linear",K98*J98*(G98/100),IF(I98>0,(1+((G98/100)*J98))^(1/(I98*365))-1,0)) -> 0.020376871 | S98: =IF(D98="Linear",L98*J98*(G98/100),(1+((G98/100)*J98))^(1/365)-1) -> 0.00010086529 | T98: =IF(D98="Linear",M98*J98*(G98/100),(1+((G98/100)*J98))^(7/365)-1) -> 0.00070627069 | U98: =IF(D98="Linear",N98*J98*(G98/100),(1+((G98/100)*J98))^(30/365)-1) -> 0.0030303884 | V98: =IF(D98="Linear",O98*J98*(G98/100),(1+((G98/100)*J98))-1) -> 0.0375 | W98: =IF(D98="Linear",P98*J98*(G98/100),(1+((G98/100)*J98))^5-1) -> 0.20209981 | X98: =IF(D98="Linear",Q98*J98*(G98/100),(1+((G98/100)*J98))^10-1) -> 0.44504394 | Y98: Illiquid alternative asset; low turnover | Z98: /mnt/data/edge_analysis9.md
... A181: 9 | B181: Lottery | D181: Linear | E181: raw | F181: Multi-State Cash4Life | G181: -55 | H181: Per Decision | I181: 0.1 | J181: 0.005 | K181: =1 -> 1 | L181: =I181 -> 0.1 | M181: =I181*7 -> 0.7 | N181: =I181*30 -> 3 | O181: =I181*365 -> 36.5 | P181: =I181*1825 -> 182.5 | Q181: =I181*3650 -> 365 | R181: =IF(D181="Linear",K181*J181*(G181/100),IF(I181>0,(1+((G181/100)*J181))^(1/(I181*365))-1,0)) -> -0.00275 | S181: =IF(D181="Linear",L181*J181*(G181/100),(1+((G181/100)*J181))^(1/365)-1) -> -0.000275 | T181: =IF(D181="Linear",M181*J181*(G181/100),(1+((G181/100)*J181))^(7/365)-1) -> -0.001925 | U181: =IF(D181="Linear",N181*J181*(G181/100),(1+((G181/100)*J181))^(30/365)-1) -> -0.00825 | V181: =IF(D181="Linear",O181*J181*(G181/100),(1+((G181/100)*J181))-1) -> -0.100375 | W181: =IF(D181="Linear",P181*J181*(G181/100),(1+((G181/100)*J181))^5-1) -> -0.501875 | X181: =IF(D181="Linear",Q181*J181*(G181/100),(1+((G181/100)*J181))^10-1) -> -1.00375 | Y181: Occasional jackpot-ticket purchase | Z181: /mnt/data/edge_analysis9.md

Sheet Category_Summary
A1: Category | B1: Items | C1: Avg_DU_per_Day | D1: Avg_CED | E1: Avg_Original_Edge | F1: Avg_Std_1Y | G1: Avg_Std_10Y
A2: Active Trading | B2: =COUNTIF(Standardized_Model!$B$2:$B$181,A2) -> 10 | C2: =SUMIF(Standardized_Model!$B$2:$B$181,A2,Standardized_Model!$I$2:$I$181)/B2 -> 5.03 | D2: =SUMIF(Standardized_Model!$B$2:$B$181,A2,Standardized_Model!$J$2:$J$181)/B2 -> 0.08 | E2: =SUMIF(Standardized_Model!$B$2:$B$181,A2,Standardized_Model!$G$2:$G$181)/B2 -> -20.985 | F2: =SUMIF(Standardized_Model!$B$2:$B$181,A2,Standardized_Model!$V$2:$V$181)/B2 -> -0.0041455 | G2: =SUMIF(Standardized_Model!$B$2:$B$181,A2,Standardized_Model!$X$2:$X$181)/B2 -> -0.035892351
A3: Bonds | B3: =COUNTIF(Standardized_Model!$B$2:$B$181,A3) -> 16 | C3: =SUMIF(Standardized_Model!$B$2:$B$181,A3,Standardized_Model!$I$2:$I$181)/B3 -> 0.01 | D3: =SUMIF(Standardized_Model!$B$2:$B$181,A3,Standardized_Model!$J$2:$J$181)/B3 -> 1 | E3: =SUMIF(Standardized_Model!$B$2:$B$181,A3,Standardized_Model!$G$2:$G$181)/B3 -> 3.41875 | F3: =SUMIF(Standardized_Model!$B$2:$B$181,A3,Standardized_Model!$V$2:$V$181)/B3 -> 0.0341875 | G3: =SUMIF(Standardized_Model!$B$2:$B$181,A3,Standardized_Model!$X$2:$X$181)/B3 -> 0.40601519
A4: Casino Gambling | B4: =COUNTIF(Standardized_Model!$B$2:$B$181,A4) -> 21 | C4: =SUMIF(Standardized_Model!$B$2:$B$181,A4,Standardized_Model!$I$2:$I$181)/B4 -> 107.38095 | D4: =SUMIF(Standardized_Model!$B$2:$B$181,A4,Standardized_Model!$J$2:$J$181)/B4 -> 0.0040952381 | E4: =SUMIF(Standardized_Model!$B$2:$B$181,A4,Standardized_Model!$G$2:$G$181)/B4 -> -6.4742857 | F4: =SUMIF(Standardized_Model!$B$2:$B$181,A4,Standardized_Model!$V$2:$V$181)/B4 -> -4.0132619 | G4: =SUMIF(Standardized_Model!$B$2:$B$181,A4,Standardized_Model!$X$2:$X$181)/B4 -> -40.132619
A5: Collectibles | B5: =COUNTIF(Standardized_Model!$B$2:$B$181,A5) -> 11 | C5: =SUMIF(Standardized_Model!$B$2:$B$181,A5,Standardized_Model!$I$2:$I$181)/B5 -> 0.018636364 | D5: =SUMIF(Standardized_Model!$B$2:$B$181,A5,Standardized_Model!$J$2:$J$181)/B5 -> 0.59090909 | E5: =SUMIF(Standardized_Model!$B$2:$B$181,A5,Standardized_Model!$G$2:$G$181)/B5 -> -4.7890909 | F5: =SUMIF(Standardized_Model!$B$2:$B$181,A5,Standardized_Model!$V$2:$V$181)/B5 -> -9.0909091e-06 | G5: =SUMIF(Standardized_Model!$B$2:$B$181,A5,Standardized_Model!$X$2:$X$181)/B5 -> 0.077375407
A6: Cryptocurrency | B6: =COUNTIF(Standardized_Model!$B$2:$B$181,A6) -> 10 | C6: =SUMIF(Standardized_Model!$B$2:$B$181,A6,Standardized_Model!$I$2:$I$181)/B6 -> 0.084 | D6: =SUMIF(Standardized_Model!$B$2:$B$181,A6,Standardized_Model!$J$2:$J$181)/B6 -> 0.56 | E6: =SUMIF(Standardized_Model!$B$2:$B$181,A6,Standardized_Model!$G$2:$G$181)/B6 -> 3.935 | F6: =SUMIF(Standardized_Model!$B$2:$B$181,A6,Standardized_Model!$V$2:$V$181)/B6 -> 0.075295 | G6: =SUMIF(Standardized_Model!$B$2:$B$181,A6,Standardized_Model!$X$2:$X$181)/B6 -> 2.8898845
A7: Lottery | B7: =COUNTIF(Standardized_Model!$B$2:$B$181,A7) -> 9 | C7: =SUMIF(Standardized_Model!$B$2:$B$181,A7,Standardized_Model!$I$2:$I$181)/B7 -> 0.2 | D7: =SUMIF(Standardized_Model!$B$2:$B$181,A7,Standardized_Model!$J$2:$J$181)/B7 -> 0.005 | E7: =SUMIF(Standardized_Model!$B$2:$B$181,A7,Standardized_Model!$G$2:$G$181)/B7 -> -41.555556 | F7: =SUMIF(Standardized_Model!$B$2:$B$181,A7,Standardized_Model!$V$2:$V$181)/B7 -> -0.14437778 | G7: =SUMIF(Standardized_Model!$B$2:$B$181,A7,Standardized_Model!$X$2:$X$181)/B7 -> -1.4437778
A8: Options & Derivatives | B8: =COUNTIF(Standardized_Model!$B$2:$B$181,A8) -> 14 | C8: =SUMIF(Standardized_Model!$B$2:$B$181,A8,Standardized_Model!$I$2:$I$181)/B8 -> 1.8757143 | D8: =SUMIF(Standardized_Model!$B$2:$B$181,A8,Standardized_Model!$J$2:$J$181)/B8 -> 0.27357143 | E8: =SUMIF(Standardized_Model!$B$2:$B$181,A8,Standardized_Model!$G$2:$G$181)/B8 -> -10.503571 | F8: =SUMIF(Standardized_Model!$B$2:$B$181,A8,Standardized_Model!$V$2:$V$181)/B8 -> -3.6278636 | G8: =SUMIF(Standardized_Model!$B$2:$B$181,A8,Standardized_Model!$X$2:$X$181)/B8 -> -36.257814
A9: Poker & Skill-Based | B9: =COUNTIF(Standardized_Model!$B$2:$B$181,A9) -> 14 | C9: =SUMIF(Standardized_Model!$B$2:$B$181,A9,Standardized_Model!$I$2:$I$181)/B9 -> 123.13571 | D9: =SUMIF(Standardized_Model!$B$2:$B$181,A9,Standardized_Model!$J$2:$J$181)/B9 -> 0.010142857 | E9: =SUMIF(Standardized_Model!$B$2:$B$181,A9,Standardized_Model!$G$2:$G$181)/B9 -> -2.6757143 | F9: =SUMIF(Standardized_Model!$B$2:$B$181,A9,Standardized_Model!$V$2:$V$181)/B9 -> -0.97183857 | G9: =SUMIF(Standardized_Model!$B$2:$B$181,A9,Standardized_Model!$X$2:$X$181)/B9 -> -9.7183857
A10: Prediction Markets | B10: =COUNTIF(Standardized_Model!$B$2:$B$181,A10) -> 12 | C10: =SUMIF(Standardized_Model!$B$2:$B$181,A10,Standardized_Model!$I$2:$I$181)/B10 -> 0.39583333 | D10: =SUMIF(Standardized_Model!$B$2:$B$181,A10,Standardized_Model!$J$2:$J$181)/B10 -> 0.03 | E10: =SUMIF(Standardized_Model!$B$2:$B$181,A10,Standardized_Model!$G$2:$G$181)/B10 -> -5.0833333 | F10: =SUMIF(Standardized_Model!$B$2:$B$181,A10,Standardized_Model!$V$2:$V$181)/B10 -> -0.22652812 | G10: =SUMIF(Standardized_Model!$B$2:$B$181,A10,Standardized_Model!$X$2:$X$181)/B10 -> -2.2652813
A11: Real Estate | B11: =COUNTIF(Standardized_Model!$B$2:$B$181,A11) -> 12 | C11: =SUMIF(Standardized_Model!$B$2:$B$181,A11,Standardized_Model!$I$2:$I$181)/B11 -> 0.0043333333 | D11: =SUMIF(Standardized_Model!$B$2:$B$181,A11,Standardized_Model!$J$2:$J$181)/B11 -> 0.96666667 | E11: =SUMIF(Standardized_Model!$B$2:$B$181,A11,Standardized_Model!$G$2:$G$181)/B11 -> 3.9566667 | F11: =SUMIF(Standardized_Model!$B$2:$B$181,A11,Standardized_Model!$V$2:$V$181)/B11 -> 0.0399 | G11: =SUMIF(Standardized_Model!$B$2:$B$181,A11,Standardized_Model!$X$2:$X$181)/B11 -> 0.6617072
A12: Sports Betting | B12: =COUNTIF(Standardized_Model!$B$2:$B$181,A12) -> 18 | C12: =SUMIF(Standardized_Model!$B$2:$B$181,A12,Standardized_Model!$I$2:$I$181)/B12 -> 1.5922222 | D12: =SUMIF(Standardized_Model!$B$2:$B$181,A12,Standardized_Model!$J$2:$J$181)/B12 -> 0.017777778 | E12: =SUMIF(Standardized_Model!$B$2:$B$181,A12,Standardized_Model!$G$2:$G$181)/B12 -> -14.036111 | F12: =SUMIF(Standardized_Model!$B$2:$B$181,A12,Standardized_Model!$V$2:$V$181)/B12 -> -0.96694583 | G12: =SUMIF(Standardized_Model!$B$2:$B$181,A12,Standardized_Model!$X$2:$X$181)/B12 -> -9.6694583
A13: Stock Market | B13: =COUNTIF(Standardized_Model!$B$2:$B$181,A13) -> 33 | C13: =SUMIF(Standardized_Model!$B$2:$B$181,A13,Standardized_Model!$I$2:$I$181)/B13 -> 0.027272727 | D13: =SUMIF(Standardized_Model!$B$2:$B$181,A13,Standardized_Model!$J$2:$J$181)/B13 -> 0.96515152 | E13: =SUMIF(Standardized_Model!$B$2:$B$181,A13,Standardized_Model!$G$2:$G$181)/B13 -> 6.5581818 | F13: =SUMIF(Standardized_Model!$B$2:$B$181,A13,Standardized_Model!$V$2:$V$181)/B13 -> 0.072642424 | G13: =SUMIF(Standardized_Model!$B$2:$B$181,A13,Standardized_Model!$X$2:$X$181)/B13 -> 1.1276843

Sheet Dashboard
A1: Edge Spectrum V9 - Dashboard
A3: Metric | B3: Value
A4: Rows in model | B4: 180
A5: Categories | B5: 12
A6: Source file | B6: edge_analysis9.md
A8: Category | B8: Avg Std 1Y Return | D8: Category | E8: Avg Std 10Y Return | G8: Category | H8: Avg DU/Day
A9: Active Trading | B9: =Category_Summary!F2 -> -0.0041455 | D9: Active Trading | E9: =Category_Summary!G2 -> -0.035892351 | G9: Active Trading | H9: =Category_Summary!C2 -> 5.03
A10: Bonds | B10: =Category_Summary!F3 -> 0.0341875 | D10: Bonds | E10: =Category_Summary!G3 -> 0.40601519 | G10: Bonds | H10: =Category_Summary!C3 -> 0.01
A11: Casino Gambling | B11: =Category_Summary!F4 -> -4.0132619 | D11: Casino Gambling | E11: =Category_Summary!G4 -> -40.132619 | G11: Casino Gambling | H11: =Category_Summary!C4 -> 107.38095
A12: Collectibles | B12: =Category_Summary!F5 -> -9.0909091e-06 | D12: Collectibles | E12: =Category_Summary!G5 -> 0.077375407 | G12: Collectibles | H12: =Category_Summary!C5 -> 0.018636364
A13: Cryptocurrency | B13: =Category_Summary!F6 -> 0.075295 | D13: Cryptocurrency | E13: =Category_Summary!G6 -> 2.8898845 | G13: Cryptocurrency | H13: =Category_Summary!C6 -> 0.084
A14: Lottery | B14: =Category_Summary!F7 -> -0.14437778 | D14: Lottery | E14: =Category_Summary!G7 -> -1.4437778 | G14: Lottery | H14: =Category_Summary!C7 -> 0.2
A15: Options & Derivatives | B15: =Category_Summary!F8 -> -3.6278636 | D15: Options & Derivatives | E15: =Category_Summary!G8 -> -36.257814 | G15: Options & Derivatives | H15: =Category_Summary!C8 -> 1.8757143
A16: Poker & Skill-Based | B16: =Category_Summary!F9 -> -0.97183857 | D16: Poker & Skill-Based | E16: =Category_Summary!G9 -> -9.7183857 | G16: Poker & Skill-Based | H16: =Category_Summary!C9 -> 123.13571
A17: Prediction Markets | B17: =Category_Summary!F10 -> -0.22652812 | D17: Prediction Markets | E17: =Category_Summary!G10 -> -2.2652813 | G17: Prediction Markets | H17: =Category_Summary!C10 -> 0.39583333
A18: Real Estate | B18: =Category_Summary!F11 -> 0.0399 | D18: Real Estate | E18: =Category_Summary!G11 -> 0.6617072 | G18: Real Estate | H18: =Category_Summary!C11 -> 0.0043333333
A19: Sports Betting | B19: =Category_Summary!F12 -> -0.96694583 | D19: Sports Betting | E19: =Category_Summary!G12 -> -9.6694583 | G19: Sports Betting | H19: =Category_Summary!C12 -> 1.5922222
A20: Stock Market | B20: =Category_Summary!F13 -> 0.072642424 | D20: Stock Market | E20: =Category_Summary!G13 -> 1.1276843 | G20: Stock Market | H20: =Category_Summary!C13 -> 0.027272727
E42: Interpretation: higher DU/day means more decision frequency. Standardized returns are driven by OriginalEdgePct, DU/day, and CED. Edit assumptions on the Standardized_Model sheet.
